Workbook
Name MyBattery: Dashboard!$G$11
Name MyCity: Dashboard!$G$7
Name MyLat: Dashboard!$G$8
Name MyLong: Dashboard!$G$9
Name MyState: Dashboard!$G$10
Name VehicleRangeKm: Dashboard!$G$12

Sheet EVRawDataset
A4: name | B4: state | C4: city | D4: address | E4: lattitude | F4: longitude | G4: type
A5: Neelkanth Star DC Charging Station | B5: Haryana | C5: Gurugram | D5: Neelkanth Star Karnal, NH 44, Gharunda, Kutail, Haryana 132114 | E5: 29.6019 | F5: 76.9803 | G5: 12
A6: Galleria DC Charging Station | B6: Haryana | C6: Gurugram | D6: DLF Phase IV, Sector 28, Gurugram, Haryana 122022 | E6: 28.4673 | F6: 77.0818 | G6: 12
A7: Highway Xpress (Jaipur-Delhi) DC charging station | B7: Rajasthan | C7: Behror | D7: Jaipur to Delhi Road, Behror Midway, Behror, Rajasthan 301701 | E7: 27.8751 | F7: 76.276 | G7: 12
A8: Food Carnival DC Charging Station | B8: Uttar Pradesh | C8: Khatauli | D8: Fun and Food Carnival, NH 58, Khatauli Bypass, Bhainsi, Uttar Pradesh 251201 | E8: 29.3105 | F8: 77.7218 | G8: 12
A9: Food Carnival AC Charging Station | B9: Uttar Pradesh | C9: Khatauli | D9: NH 58, Khatauli Bypass, Bhainsi, Uttar Pradesh 251201 | E9: 29.3105 | F9: 77.7218 | G9: 12
A10: Krishna Hansraj Hotel Una DC charging station | B10: Himachal Pradesh | C10: Una | D10: Old Hoshiarpur Rd, Una, Himachal Pradesh 174303 | E10: 31.4668 | F10: 76.2568 | G10: 12
A11: SG Jabli DC Charging Station | B11: Himachal Pradesh | C11: Kasauli | D11: VPO - Jabli, NH-22, Teh, Kasauli, Himachal Pradesh | E11: 30.879 | F11: 76.9948 | G11: 12
A12: SG Jabli AC Charging Station | B12: Himachal Pradesh | C12: Kasauli | D12: VPO - Jabli, NH-22, Teh, Kasauli, Himachal Pradesh | E12: 30.879 | F12: 76.9948 | G12: 12
A13: SG Karnal DC Charging Station | B13: Haryana | C13: Karnal | D13: 131 km Milestone, G. T, GT Karnal Rd, near Karna Lake, Karnal, Haryana 132001 | E13: 29.7379 | F13: 76.9756 | G13: 12
A14: SG Karnal AC Charging Station | B14: Haryana | C14: Karnal | D14: 131 km Milestone, G. T, GT Karnal Rd, near Karna Lake, Karnal, Haryana 132001 | E14: 29.7379 | F14: 76.9756 | G14: 12
A15: Neelkanth Star AC charging station | B15: Haryana | C15: karnal | D15: Neelkanth Star Karnal, NH 44, Gharunda, Kutail, Haryana 132114 | E15: 29.6019 | F15: 76.9803 | G15: 12
A16: Deep Brothers IOCL AC Charging Station | B16: Haryana | C16: Darbaripur | D16: Deep Brothers, Palra Road, Darbaripur | E16: 28.3861 | F16: 77.0063 | G16: 12
... A94: New Udaan Bhawan AdPod 2 | B94: Haryana | C94: Gurgaon | D94: Indira Gandhi International Airport | E94: 28.5537 | F94: 77.0943 | G94: 12
A95: TDPL EV Charging Station 1 | B95: Rajasthan | C95: Jaipur | E95: 26.9159 | F95: 75.723 | G95: 12
A96: Hotel The Executive Inn AC Charging Station | B96: Maharashtra | C96: Shirdi | E96: 19.7592 | F96: 74.4763 | G96: 12
A97: Hotel Bliss County DC Charging Station | B97: Maharashtra | C97: Dhule | E97: 20.8292 | F97: 74.7485 | G97: 12
A98: Savoy Suites Manesar | B98: Haryana | C98: Gurugram | E98: 28.3664 | F98: 76.9436 | G98: 12
A99: MV EV DC Charging Station | B99: Maharashtra | C99: Dahanu | E99: 19.9883 | F99: 72.7488 | G99: 12
A100: Jamoliwala AC Charging Station | B100: Uttarakhand | C100: Dehradun | E100: 78.0654 | F100: 30.3886 | G100: 12
A101: TDPL EV Charging Station 2 | B101: Rajasthan | C101: Jaipur | E101: 26.8807 | F101: 75.6143 | G101: 12
A102: Bhajan Singh Da Dhabha DC Charging Station | B102: Maharashtra | C102: Talegaon Dabhade | E102: 18.7005 | F102: 73.6933 | G102: 12
A103: Hotel Prabhat Palace DC Charging Station | B103: Jammu and Kashmir | C103: Katra | E103: 32.9899 | F103: 74.9255 | G103: 12
A104: TSREDCO Test Charging Station | B104: Telangana | C104: HYDERBAD | E104: 17.4123 | F104: 78.4598 | G104: 12
A105: TSREDCO Test Charging Station 1 | B105: Telangana | C105: HYDERBAD | E105: 17.4125 | F105: 78.4603 | G105: 12
A106: Mehak Garden Charging Station | B106: Haryana | C106: Sirsa | E106: 29.528 | F106: 75.1325 | G106: 12
... A130: Monsoon Breeze AdPod | B130: Haryana | C130: Gurugram | E130: 28.3687 | F130: 76.966 | G130: 12
A131: Decathlon Anubhava | B131: Maharashtra | C131: bengaluru | D131: Survey No 78/10, A2, Bellary Road, Bangalore Airport Road, Chikkajala, | E131: 13.169102 | F131: 77.632018 | G131: 6
A132: Forum Shantiniketan | B132: Maharashtra | C132: bengaluru | D132: Whitefield Main Road, Hoodi, Thigalarapalya, Krishnarajapura, Bengaluru, Karnataka | E132: 12.989235 | F132: 77.727908 | G132: 6
A133: Park Square Mall | B133: Maharashtra | C133: bengaluru | D133: UB1 Parking.40, ITPB Main Road, International Tech Park, Whitefield Main Rd, Pattandur Agrahara, Whitefield, Bengaluru, Karnataka 560066 | E133: 12.9873 | F133: 77.736397 | G133: 6
A134: GT World Mall | B134: Maharashtra | C134: bengaluru | D134: Magadi Main Rd, next to Prasanna Theatre, Cholourpalya, Bengaluru, Karnataka 560023 | E134: 12.974 | F134: 77.551399 | G134: 6
A135: Orion Mall | B135: Maharashtra | C135: bengaluru | D135: Dr Rajkumar Road, Rajajinagar, | E135: 13.011065 | F135: 77.554534 | G135: 6
A136: Phoenix Market City | B136: Maharashtra | C136: pune | D136: S No 207, Viman Nagar Road, Phoenix Road, Viman Nagar, Pune, Maharashtra | E136: 18.561919 | F136: 73.916681 | G136: 6
A137: Phoenix Market City | B137: Odisha | C137: bengaluru | D137: Whitefield Main Road, Mahadevpura, Bengaluru, Karnataka 560048 | E137: 12.9971 | F137: 77.696297 | G137: 6
A138: Patel's Inn | B138: Odisha | C138: bengaluru | D138: No 1, 15th Cross, 2nd Block, Govindaraj Garden, R.T Nagar, | E138: 13.020907 | F138: 77.597984 | G138: 6
A139: Coco Jaunt 1728 - Anna Nagar | B139: Pondicherry | C139: chennai | D139: t-2, 4th Main Rd, Anna Nagar West, Anna Nagar, Chennai, Tamil Nadu 600040 | E139: 13.0902 | F139: 80.217499 | G139: 6
A140: Infinitea | B140: Punjab | C140: bengaluru | D140: 6,ESI Hospital Road HAL 2nd Stage, 100 feet road, Indiranagar, Doopanahalli, Bengaluru, Karnataka | E140: 12.969 | F140: 77.6362 | G140: 6
A141: The Only Place | B141: Punjab | C141: bengaluru | D141: Siddam Setty Complex, Museum Rd, Next To, Shanthala Nagar, Ashok Nagar, Bengaluru, Karnataka 560001 | E141: 12.9731 | F141: 77.603302 | G141: 6
A142: Fab Cafe | B142: Rajasthan | C142: bengaluru | D142: 915, Kenchena Halli Rd, Remco Bhel Layout, Kenchenhalli, RR Nagar,560098 | E142: 12.9341 | F142: 77.517197 | G142: 6
... A379: Detailing Bull | B379: Jammu & Kashmir | C379: gurugram | D379: F7, Shushant Lok 2 Near Hong Kong Bazar, Sector 57, Gurugram, Haryana 122011 | E379: 28.419524 | F379: 77.088514 | G379: 6
...

Sheet EVCleanedDataset
A4: Name | B4: State | C4: City | D4: Latitude | E4: Longitude | F4: IsFirstCity | G4: CityLevelMinimumDistance | H4: EstimatedBatteryOnArrival | I4: Distance(km) | J4: QueueLength | K4: Score | L4: Reachable
A5: Ginger Hotel, Near Kottara Chowki Junction | B5: Karnataka | C5: Mangalore | D5: 12.909027 | E5: 74.83597 | F5: =IF(COUNTIF($C$5:C5,C5)=1,1,0) -> 1 | G5: =IF(F5=1, IF(C5=MyCity, "", _xlfn.MINIFS($I$5:$I$1121,$C$5:$C$1121,C5)), "") -> 295.5661 | H5: =MAX(0, MyBattery - (EVCleanedDataset[[#This Row],[Distance(km)]]/VehicleRangeKm)*100) -> 0 | I5: =6371*ACOS(SIN(RADIANS(MyLat))*SIN(RADIANS(EVCleanedDataset[[#This Row],[Latitude]]))+COS(RADIANS(MyLat))*COS(RADIANS(EVCleanedDataset[[#This Row],[Latitude]]))*COS(RADIANS(EVCleanedDataset[[#This Row],[Longitude]]-MyLong))) -> 296.60772 | J5: =MOD(ROW()*7,10) -> 5 | K5: =((1-(EVCleanedDataset[[#This Row],[Distance(km)]]/MAX($I$5:$I$1121)))*0.4 + (1-(EVCleanedDataset[[#This Row],[QueueLength]]/MAX($J$5:$J$1121)))*0.3 + (EVCleanedDataset[[#This Row],[EstimatedBatteryOnArrival]]/100)*0.3 + (ROW()/10000000))*100 -> 48.138237 | L5: =IF(EVCleanedDataset[[#This Row],[Score]]>50,"Yes","No") -> No
A6: Jubilant Autoworks, Padukodi | B6: Karnataka | C6: Mangalore | D6: 12.923728 | E6: 74.831066 | F6: =IF(COUNTIF($C$5:C6,C6)=1,1,0) -> 0 | G6: =IF(F6=1, IF(C6=MyCity, "", _xlfn.MINIFS($I$5:$I$1121,$C$5:$C$1121,C6)), "") | H6: =MAX(0, MyBattery - (EVCleanedDataset[[#This Row],[Distance(km)]]/VehicleRangeKm)*100) -> 0 | I6: =6371*ACOS(SIN(RADIANS(MyLat))*SIN(RADIANS(EVCleanedDataset[[#This Row],[Latitude]]))+COS(RADIANS(MyLat))*COS(RADIANS(EVCleanedDataset[[#This Row],[Latitude]]))*COS(RADIANS(EVCleanedDataset[[#This Row],[Longitude]]-MyLong))) -> 296.85801 | J6: =MOD(ROW()*7,10) -> 2 | K6: =((1-(EVCleanedDataset[[#This Row],[Distance(km)]]/MAX($I$5:$I$1121)))*0.4 + (1-(EVCleanedDataset[[#This Row],[QueueLength]]/MAX($J$5:$J$1121)))*0.3 + (EVCleanedDataset[[#This Row],[EstimatedBatteryOnArrival]]/100)*0.3 + (ROW()/10000000))*100 -> 58.133863 | L6: =IF(EVCleanedDataset[[#This Row],[Score]]>50,"Yes","No") -> Yes
A7: Manipal Charging Station | B7: Karnataka | C7: Manipal | D7: 13.3334 | E7: 74.7884 | F7: =IF(COUNTIF($C$5:C7,C7)=1,1,0) -> 1 | G7: =IF(F7=1, IF(C7=MyCity, "", _xlfn.MINIFS($I$5:$I$1121,$C$5:$C$1121,C7)), "") -> 297.44093 | H7: =MAX(0, MyBattery - (EVCleanedDataset[[#This Row],[Distance(km)]]/VehicleRangeKm)*100) -> 0 | I7: =6371*ACOS(SIN(RADIANS(MyLat))*SIN(RADIANS(EVCleanedDataset[[#This Row],[Latitude]]))+COS(RADIANS(MyLat))*COS(RADIANS(EVCleanedDataset[[#This Row],[Latitude]]))*COS(RADIANS(EVCleanedDataset[[#This Row],[Longitude]]-MyLong))) -> 297.44093 | J7: =MOD(ROW()*7,10) -> 9 | K7: =((1-(EVCleanedDataset[[#This Row],[Distance(km)]]/MAX($I$5:$I$1121)))*0.4 + (1-(EVCleanedDataset[[#This Row],[QueueLength]]/MAX($J$5:$J$1121)))*0.3 + (EVCleanedDataset[[#This Row],[EstimatedBatteryOnArrival]]/100)*0.3 + (ROW()/10000000))*100 -> 34.79033 | L7: =IF(EVCleanedDataset[[#This Row],[Score]]>50,"Yes","No") -> No
A8: Tata Power | B8: Karnataka | C8: Mangalore | D8: 12.885716 | E8: 74.843476 | F8: =IF(COUNTIF($C$5:C8,C8)=1,1,0) -> 0 | G8: =IF(F8=1, IF(C8=MyCity, "", _xlfn.MINIFS($I$5:$I$1121,$C$5:$C$1121,C8)), "") | H8: =MAX(0, MyBattery - (EVCleanedDataset[[#This Row],[Distance(km)]]/VehicleRangeKm)*100) -> 0 | I8: =6371*ACOS(SIN(RADIANS(MyLat))*SIN(RADIANS(EVCleanedDataset[[#This Row],[Latitude]]))+COS(RADIANS(MyLat))*COS(RADIANS(EVCleanedDataset[[#This Row],[Latitude]]))*COS(RADIANS(EVCleanedDataset[[#This Row],[Longitude]]-MyLong))) -> 296.25943 | J8: =MOD(ROW()*7,10) -> 6 | K8: =((1-(EVCleanedDataset[[#This Row],[Distance(km)]]/MAX($I$5:$I$1121)))*0.4 + (1-(EVCleanedDataset[[#This Row],[QueueLength]]/MAX($J$5:$J$1121)))*0.3 + (EVCleanedDataset[[#This Row],[EstimatedBatteryOnArrival]]/100)*0.3 + (ROW()/10000000))*100 -> 44.811034 | L8: =IF(EVCleanedDataset[[#This Row],[Score]]>50,"Yes","No") -> No
A9: Kaup Charging Station | B9: Karnataka | C9: Kaup | D9: 13.2338 | E9: 74.7471 | F9: =IF(COUNTIF($C$5:C9,C9)=1,1,0) -> 1 | G9: =IF(F9=1, IF(C9=MyCity, "", _xlfn.MINIFS($I$5:$I$1121,$C$5:$C$1121,C9)), "") -> 302.23834 | H9: =MAX(0, MyBattery - (EVCleanedDataset[[#This Row],[Distance(km)]]/VehicleRangeKm)*100) -> 0 | I9: =6371*ACOS(SIN(RADIANS(MyLat))*SIN(RADIANS(EVCleanedDataset[[#This Row],[Latitude]]))+COS(RADIANS(MyLat))*COS(RADIANS(EVCleanedDataset[[#This Row],[Latitude]]))*COS(RADIANS(EVCleanedDataset[[#This Row],[Longitude]]-MyLong))) -> 302.23834 | J9: =MOD(ROW()*7,10) -> 3 | K9: =((1-(EVCleanedDataset[[#This Row],[Distance(km)]]/MAX($I$5:$I$1121)))*0.4 + (1-(EVCleanedDataset[[#This Row],[QueueLength]]/MAX($J$5:$J$1121)))*0.3 + (EVCleanedDataset[[#This Row],[EstimatedBatteryOnArrival]]/100)*0.3 + (ROW()/10000000))*100 -> 54.706322 | L9: =IF(EVCleanedDataset[[#This Row],[Score]]>50,"Yes","No") -> Yes
A10: Kvr Dream Vehicles, Nadal | B10: Kerala | C10: Kannur | D10: 11.83301 | E10: 75.42643 | F10: =IF(COUNTIF($C$5:C10,C10)=1,1,0) -> 1 | G10: =IF(F10=1, IF(C10=MyCity, "", _xlfn.MINIFS($I$5:$I$1121,$C$5:$C$1121,C10)), "") -> 277.64227 | H10: =MAX(0, MyBattery - (EVCleanedDataset[[#This Row],[Distance(km)]]/VehicleRangeKm)*100) -> 0 | I10: =6371*ACOS(SIN(RADIANS(MyLat))*SIN(RADIANS(EVCleanedDataset[[#This Row],[Latitude]]))+COS(RADIANS(MyLat))*COS(RADIANS(EVCleanedDataset[[#This Row],[Latitude]]))*COS(RADIANS(EVCleanedDataset[[#This Row],[Longitude]]-MyLong))) -> 284.43191 | J10: =MOD(ROW()*7,10) -> 0 | K10: =((1-(EVCleanedDataset[[#This Row],[Distance(km)]]/MAX($I$5:$I$1121)))*0.4 + (1-(EVCleanedDataset[[#This Row],[QueueLength]]/MAX($J$5:$J$1121)))*0.3 + (EVCleanedDataset[[#This Row],[EstimatedBatteryOnArrival]]/100)*0.3 + (ROW()/10000000))*100 -> 65.018216 | L10: =IF(EVCleanedDataset[[#This Row],[Score]]>50,"Yes","No") -> Yes
A11: Kundapura Charging Station | B11: Karnataka | C11: Kundapura | D11: 13.6186 | E11: 74.6919 | F11: =IF(COUNTIF($C$5:C11,C11)=1,1,0) -> 1 | G11: =IF(F11=1, IF(C11=MyCity, "", _xlfn.MINIFS($I$5:$I$1121,$C$5:$C$1121,C11)), "") -> 309.14896 | H11: =MAX(0, MyBattery - (EVCleanedDataset[[#This Row],[Distance(km)]]/VehicleRangeKm)*100) -> 0 | I11: =6371*ACOS(SIN(RADIANS(MyLat))*SIN(RADIANS(EVCleanedDataset[[#This Row],[Latitude]]))+COS(RADIANS(MyLat))*COS(RADIANS(EVCleanedDataset[[#This Row],[Latitude]]))*COS(RADIANS(EVCleanedDataset[[#This Row],[Longitude]]-MyLong))) -> 309.14896 | J11: =MOD(ROW()*7,10) -> 7 | K11: =((1-(EVCleanedDataset[[#This Row],[Distance(km)]]/MAX($I$5:$I$1121)))*0.4 + (1-(EVCleanedDataset[[#This Row],[QueueLength]]/MAX($J$5:$J$1121)))*0.3 + (EVCleanedDataset[[#This Row],[EstimatedBatteryOnArrival]]/100)*0.3 + (ROW()/10000000))*100 -> 41.251968 | L11: =IF(EVCleanedDataset[[#This Row],[Score]]>50,"Yes","No") -> No
A12: Padmashree Charging Station | B12: Karnataka | C12: Mudbidri | D12: 13.074 | E12: 75.0025 | F12: =IF(COUNTIF($C$5:C12,C12)=1,1,0) -> 1 | G12: =IF(F12=1, IF(C12=MyCity, "", _xlfn.MINIFS($I$5:$I$1121,$C$5:$C$1121,C12)), "") -> 276.11791 | H12: =MAX(0, MyBattery - (EVCleanedDataset[[#This Row],[Distance(km)]]/VehicleRangeKm)*100) -> 0 | I12: =6371*ACOS(SIN(RADIANS(MyLat))*SIN(RADIANS(EVCleanedDataset[[#This Row],[Latitude]]))+COS(RADIANS(MyLat))*COS(RADIANS(EVCleanedDataset[[#This Row],[Latitude]]))*COS(RADIANS(EVCleanedDataset[[#This Row],[Longitude]]-MyLong))) -> 276.11791 | J12: =MOD(ROW()*7,10) -> 4 | K12: =((1-(EVCleanedDataset[[#This Row],[Distance(km)]]/MAX($I$5:$I$1121)))*0.4 + (1-(EVCleanedDataset[[#This Row],[QueueLength]]/MAX($J$5:$J$1121)))*0.3 + (EVCleanedDataset[[#This Row],[EstimatedBatteryOnArrival]]/100)*0.3 + (ROW()/10000000))*100 -> 51.830524 | L12: =IF(EVCleanedDataset[[#This Row],[Score]]>50,"Yes","No") -> Yes
A13: M R A Restaurant | B13: Kerala | C13: Kannur | D13: 12.025627 | E13: 75.367177 | F13: =IF(COUNTIF($C$5:C13,C13)=1,1,0) -> 0 | G13: =IF(F13=1, IF(C13=MyCity, "", _xlfn.MINIFS($I$5:$I$1121,$C$5:$C$1121,C13)), "") | H13: =MAX(0, MyBattery - (EVCleanedDataset[[#This Row],[Distance(km)]]/VehicleRangeKm)*100) -> 0 | I13: =6371*ACOS(SIN(RADIANS(MyLat))*SIN(RADIANS(EVCleanedDataset[[#This Row],[Latitude]]))+COS(RADIANS(MyLat))*COS(RADIANS(EVCleanedDataset[[#This Row],[Latitude]]))*COS(RADIANS(EVCleanedDataset[[#This Row],[Longitude]]-MyLong))) -> 277.64227 | J13: =MOD(ROW()*7,10) -> 1 | K13: =((1-(EVCleanedDataset[[#This Row],[Distance(km)]]/MAX($I$5:$I$1121)))*0.4 + (1-(EVCleanedDataset[[#This Row],[QueueLength]]/MAX($J$5:$J$1121)))*0.3 + (EVCleanedDataset[[#This Row],[EstimatedBatteryOnArrival]]/100)*0.3 + (ROW()/10000000))*100 -> 61.803834 | L13: =IF(EVCleanedDataset[[#This Row],[Score]]>50,"Yes","No") -> Yes
A14: Ather Space Mangalore | B14: Karnataka | C14: Mangalore | D14: 12.878593 | E14: 74.851322 | F14: =IF(COUNTIF($C$5:C14,C14)=1,1,0) -> 0 | G14: =IF(F14=1, IF(C14=MyCity, "", _xlfn.MINIFS($I$5:$I$1121,$C$5:$C$1121,C14)), "") | H14: =MAX(0, MyBattery - (EVCleanedDataset[[#This Row],[Distance(km)]]/VehicleRangeKm)*100) -> 0 | I14: =6371*ACOS(SIN(RADIANS(MyLat))*SIN(RADIANS(EVCleanedDataset[[#This Row],[Latitude]]))+COS(RADIANS(MyLat))*COS(RADIANS(EVCleanedDataset[[#This Row],[Latitude]]))*COS(RADIANS(EVCleanedDataset[[#This Row],[Longitude]]-MyLong))) -> 295.5661 | J14: =MOD(ROW()*7,10) -> 8 | K14: =((1-(EVCleanedDataset[[#This Row],[Distance(km)]]/MAX($I$5:$I$1121)))*0.4 + (1-(EVCleanedDataset[[#This Row],[QueueLength]]/MAX($J$5:$J$1121)))*0.3 + (EVCleanedDataset[[#This Row],[EstimatedBatteryOnArrival]]/100)*0.3 + (ROW()/10000000))*100 -> 38.156571 | L14: =IF(EVCleanedDataset[[#This Row],[Score]]>50,"Yes","No") -> No
A15: Waterwoods Lodge & Resort Ac Charging Station | B15: Karnataka | C15: Metikuppe | D15: 11.9377 | E15: 76.2655 | F15: =IF(COUNTIF($C$5:C15,C15)=1,1,0) -> 1 | G15: =IF(F15=1, IF(C15=MyCity, "", _xlfn.MINIFS($I$5:$I$1121,$C$5:$C$1121,C15)), "") -> 208.99013 | H15: =MAX(0, MyBattery - (EVCleanedDataset[[#This Row],[Distance(km)]]/VehicleRangeKm)*100) -> 0.33662193 | I15: =6371*ACOS(SIN(RADIANS(MyLat))*SIN(RADIANS(EVCleanedDataset[[#This Row],[Latitude]]))+COS(RADIANS(MyLat))*COS(RADIANS(EVCleanedDataset[[#This Row],[Latitude]]))*COS(RADIANS(EVCleanedDataset[[#This Row],[Longitude]]-MyLong))) -> 208.99013 | J15: =MOD(ROW()*7,10) -> 5 | K15: =((1-(EVCleanedDataset[[#This Row],[Distance(km)]]/MAX($I$5:$I$1121)))*0.4 + (1-(EVCleanedDataset[[#This Row],[QueueLength]]/MAX($J$5:$J$1121)))*0.3 + (EVCleanedDataset[[#This Row],[EstimatedBatteryOnArrival]]/100)*0.3 + (ROW()/10000000))*100 -> 49.773964 | L15: =IF(EVCleanedDataset[[#This Row],[Score]]>50,"Yes","No") -> No
A16: The Forum Fiza Mall Ac Charging Station Mangalore | B16: Karnataka | C16: Mangalore | D16: 12.8576 | E16: 74.8383 | F16: =IF(COUNTIF($C$5:C16,C16)=1,1,0) -> 0 | G16: =IF(F16=1, IF(C16=MyCity, "", _xlfn.MINIFS($I$5:$I$1121,$C$5:$C$1121,C16)), "") | H16: =MAX(0, MyBattery - (EVCleanedDataset[[#This Row],[Distance(km)]]/VehicleRangeKm)*100) -> 0 | I16: =6371*ACOS(SIN(RADIANS(MyLat))*SIN(RADIANS(EVCleanedDataset[[#This Row],[Latitude]]))+COS(RADIANS(MyLat))*COS(RADIANS(EVCleanedDataset[[#This Row],[Latitude]]))*COS(RADIANS(EVCleanedDataset[[#This Row],[Longitude]]-MyLong))) -> 297.38642 | J16: =MOD(ROW()*7,10) -> 2 | K16: =((1-(EVCleanedDataset[[#This Row],[Distance(km)]]/MAX($I$5:$I$1121)))*0.4 + (1-(EVCleanedDataset[[#This Row],[QueueLength]]/MAX($J$5:$J$1121)))*0.3 + (EVCleanedDataset[[#This Row],[EstimatedBatteryOnArrival]]/100)*0.3 + (ROW()/10000000))*100 -> 58.124708 | L16: =IF(EVCleanedDataset[[#This Row],[Score]]>50,"Yes","No") -> Yes
... A1121: Pragati Trading, Nh 37 | B1121: Assam | C1121: Jorhat | D1121: 26.747049 | E1121: 94.168072 | F1121: =IF(COUNTIF($C$5:C1121,C1121)=1,1,0) -> 1 | G1121: =IF(F1121=1, IF(C1121=MyCity, "", _xlfn.MINIFS($I$5:$I$1121,$C$5:$C$1121,C1121)), "") -> 2283.7295 | H1121: =MAX(0, MyBattery - (EVCleanedDataset[[#This Row],[Distance(km)]]/VehicleRangeKm)*100) -> 0 | I1121: =6371*ACOS(SIN(RADIANS(MyLat))*SIN(RADIANS(EVCleanedDataset[[#This Row],[Latitude]]))+COS(RADIANS(MyLat))*COS(RADIANS(EVCleanedDataset[[#This Row],[Latitude]]))*COS(RADIANS(EVCleanedDataset[[#This Row],[Longitude]]-MyLong))) -> 2283.7295 | J1121: =MOD(ROW()*7,10) -> 7 | K1121: =((1-(EVCleanedDataset[[#This Row],[Distance(km)]]/MAX($I$5:$I$1121)))*0.4 + (1-(EVCleanedDataset[[#This Row],[QueueLength]]/MAX($J$5:$J$1121)))*0.3 + (EVCleanedDataset[[#This Row],[EstimatedBatteryOnArrival]]/100)*0.3 + (ROW()/10000000))*100 -> 6.6778767 | L1121: =IF(EVCleanedDataset[[#This Row],[Score]]>50,"Yes","No") -> No

Sheet Dashboard
F3: Total Charging Stations in India | G3: Total Charging Stations in State | H3: Reachable Stations
F4: =COUNTA(EVCleanedDataset[Name]) -> 1117 | G4: =COUNTIF(EVCleanedDataset!$B$5:$B$1121,MyState) -> 127 | H4: =COUNTIF(EVCleanedDataset[Reachable],"Yes") -> 308
F6: User Input | G6: Values | I6: Rank | J6: Nearest Top 5 Recommendated EV Stations | K6: Battery Level | L6: Queue Length | M6: Distance (km) | N6: Score | O6: Reachable | Q6: Rank | R6: Nearest 5 Cities to Location | S6: Distance (km)
F7: City | G7: Bangalore | I7: 1 | J7: =INDEX(EVCleanedDataset!$A$5:$A$1121, MATCH(LARGE(EVCleanedDataset!$K$5:$K$1121,$I7), EVCleanedDataset!$K$5:$K$1121,0)) -> Fuel Zone -Indian Oil Petrol Pump | K7: =INDEX(EVCleanedDataset!$H$5:$H$1121, MATCH(LARGE(EVCleanedDataset!$K$5:$K$1121,$I7), EVCleanedDataset!$K$5:$K$1121,0)) -> 61.746965 | L7: =INDEX(EVCleanedDataset!$J$5:$J$1121, MATCH(LARGE(EVCleanedDataset!$K$5:$K$1121,$I7), EVCleanedDataset!$K$5:$K$1121,0)) -> 0 | M7: =INDEX(EVCleanedDataset!$I$5:$I$1121, MATCH(LARGE(EVCleanedDataset!$K$5:$K$1121,$I7), EVCleanedDataset!$K$5:$K$1121,0)) -> 24.759106 | N7: =LARGE(EVCleanedDataset!$K$5:$K$1121,$I7) -> 88.090928 | O7: =INDEX(EVCleanedDataset!$L$5:$L$1121, MATCH(LARGE(EVCleanedDataset!$K$5:$K$1121,$I7), EVCleanedDataset!$K$5:$K$1121,0)) -> Yes | Q7: 1 | R7: =INDEX(EVCleanedDataset!$C$5:$C$1121, MATCH(SMALL(EVCleanedDataset!$G$5:$G$1121,$Q7), EVCleanedDataset!$G$5:$G$1121,0)) -> Tumakuru | S7: =SMALL(EVCleanedDataset!$G$5:$G$1121,$Q7) -> 39.012034
F8: Latitude | G8: =AVERAGEIF(EVCleanedDataset[City],MyCity,EVCleanedDataset[Latitude]) -> 13.349118 | I8: 2 | J8: =INDEX(EVCleanedDataset!$A$5:$A$1121, MATCH(LARGE(EVCleanedDataset!$K$5:$K$1121,$I8), EVCleanedDataset!$K$5:$K$1121,0)) -> Bescom Banaswadi | K8: =INDEX(EVCleanedDataset!$H$5:$H$1121, MATCH(LARGE(EVCleanedDataset!$K$5:$K$1121,$I8), EVCleanedDataset!$K$5:$K$1121,0)) -> 57.258266 | L8: =INDEX(EVCleanedDataset!$J$5:$J$1121, MATCH(LARGE(EVCleanedDataset!$K$5:$K$1121,$I8), EVCleanedDataset!$K$5:$K$1121,0)) -> 0 | M8: =INDEX(EVCleanedDataset!$I$5:$I$1121, MATCH(LARGE(EVCleanedDataset!$K$5:$K$1121,$I8), EVCleanedDataset!$K$5:$K$1121,0)) -> 38.225202 | N8: =LARGE(EVCleanedDataset!$K$5:$K$1121,$I8) -> 86.509657 | O8: =INDEX(EVCleanedDataset!$L$5:$L$1121, MATCH(LARGE(EVCleanedDataset!$K$5:$K$1121,$I8), EVCleanedDataset!$K$5:$K$1121,0)) -> Yes | Q8: 2 | R8: =INDEX(EVCleanedDataset!$C$5:$C$1121, MATCH(SMALL(EVCleanedDataset!$G$5:$G$1121,$Q8), EVCleanedDataset!$G$5:$G$1121,0)) -> Kodikonda | S8: =SMALL(EVCleanedDataset!$G$5:$G$1121,$Q8) -> 57.777113
F9: Longitude | G9: =AVERAGEIF(EVCleanedDataset[City], MyCity,EVCleanedDataset[Longitude]) -> 77.537508 | I9: 3 | J9: =INDEX(EVCleanedDataset!$A$5:$A$1121, MATCH(LARGE(EVCleanedDataset!$K$5:$K$1121,$I9), EVCleanedDataset!$K$5:$K$1121,0)) -> Hotel Sri Nanjundeshwara | K9: =INDEX(EVCleanedDataset!$H$5:$H$1121, MATCH(LARGE(EVCleanedDataset!$K$5:$K$1121,$I9), EVCleanedDataset!$K$5:$K$1121,0)) -> 56.995989 | L9: =INDEX(EVCleanedDataset!$J$5:$J$1121, MATCH(LARGE(EVCleanedDataset!$K$5:$K$1121,$I9), EVCleanedDataset!$K$5:$K$1121,0)) -> 0 | M9: =INDEX(EVCleanedDataset!$I$5:$I$1121, MATCH(LARGE(EVCleanedDataset!$K$5:$K$1121,$I9), EVCleanedDataset!$K$5:$K$1121,0)) -> 39.012034 | N9: =LARGE(EVCleanedDataset!$K$5:$K$1121,$I9) -> 86.415693 | O9: =INDEX(EVCleanedDataset!$L$5:$L$1121, MATCH(LARGE(EVCleanedDataset!$K$5:$K$1121,$I9), EVCleanedDataset!$K$5:$K$1121,0)) -> Yes | Q9: 3 | R9: =INDEX(EVCleanedDataset!$C$5:$C$1121, MATCH(SMALL(EVCleanedDataset!$G$5:$G$1121,$Q9), EVCleanedDataset!$G$5:$G$1121,0)) -> Hosur | S9: =SMALL(EVCleanedDataset!$G$5:$G$1121,$Q9) -> 79.272191
F10: State | G10: =IFERROR(INDEX(EVCleanedDataset!$B$5:$B$1121, MATCH($G$7, EVCleanedDataset!$C$5:$C$1121, 0)), "Not Found") -> Karnataka | I10: 4 | J10: =INDEX(EVCleanedDataset!$A$5:$A$1121, MATCH(LARGE(EVCleanedDataset!$K$5:$K$1121,$I10), EVCleanedDataset!$K$5:$K$1121,0)) -> Bescom Mahadevpura | K10: =INDEX(EVCleanedDataset!$H$5:$H$1121, MATCH(LARGE(EVCleanedDataset!$K$5:$K$1121,$I10), EVCleanedDataset!$K$5:$K$1121,0)) -> 55.611027 | L10: =INDEX(EVCleanedDataset!$J$5:$J$1121, MATCH(LARGE(EVCleanedDataset!$K$5:$K$1121,$I10), EVCleanedDataset!$K$5:$K$1121,0)) -> 0 | M10: =INDEX(EVCleanedDataset!$I$5:$I$1121, MATCH(LARGE(EVCleanedDataset!$K$5:$K$1121,$I10), EVCleanedDataset!$K$5:$K$1121,0)) -> 43.166919 | N10: =LARGE(EVCleanedDataset!$K$5:$K$1121,$I10) -> 85.92753 | O10: =INDEX(EVCleanedDataset!$L$5:$L$1121, MATCH(LARGE(EVCleanedDataset!$K$5:$K$1121,$I10), EVCleanedDataset!$K$5:$K$1121,0)) -> Yes | Q10: 4 | R10: =INDEX(EVCleanedDataset!$C$5:$C$1121, MATCH(SMALL(EVCleanedDataset!$G$5:$G$1121,$Q10), EVCleanedDataset!$G$5:$G$1121,0)) -> Yediyur | S10: =SMALL(EVCleanedDataset!$G$5:$G$1121,$Q10) -> 81.452711
F11: Battery Level | G11: 70 | I11: 5 | J11: =INDEX(EVCleanedDataset!$A$5:$A$1121, MATCH(LARGE(EVCleanedDataset!$K$5:$K$1121,$I11), EVCleanedDataset!$K$5:$K$1121,0)) -> Bescom Indiranagar | K11: =INDEX(EVCleanedDataset!$H$5:$H$1121, MATCH(LARGE(EVCleanedDataset!$K$5:$K$1121,$I11), EVCleanedDataset!$K$5:$K$1121,0)) -> 55.249328 | L11: =INDEX(EVCleanedDataset!$J$5:$J$1121, MATCH(LARGE(EVCleanedDataset!$K$5:$K$1121,$I11), EVCleanedDataset!$K$5:$K$1121,0)) -> 0 | M11: =INDEX(EVCleanedDataset!$I$5:$I$1121, MATCH(LARGE(EVCleanedDataset!$K$5:$K$1121,$I11), EVCleanedDataset!$K$5:$K$1121,0)) -> 44.252015 | N11: =LARGE(EVCleanedDataset!$K$5:$K$1121,$I11) -> 85.800815 | O11: =INDEX(EVCleanedDataset!$L$5:$L$1121, MATCH(LARGE(EVCleanedDataset!$K$5:$K$1121,$I11), EVCleanedDataset!$K$5:$K$1121,0)) -> Yes | Q11: 5 | R11: =INDEX(EVCleanedDataset!$C$5:$C$1121, MATCH(SMALL(EVCleanedDataset!$G$5:$G$1121,$Q11), EVCleanedDataset!$G$5:$G$1121,0)) -> Hatna | S11: =SMALL(EVCleanedDataset!$G$5:$G$1121,$Q11) -> 86.946627
F12: Vehicle Range (km) | G12: 300
O18: Reachable | P18: =COUNTIF(EVCleanedDataset[Reachable],"Yes") -> 308
O19: Non-Reachable | P19: =COUNTIF(EVCleanedDataset[Reachable],"No") -> 809
